Workbook

Sheet 0-Паспорт проекта
G1: header_first | H1: HeaderFirst
A2: Номер | B2: Название | C2: Значение | E2: ИсточникИнформации | F2: Рекомендации | G2: key | H2: k9 | I2: needToSend | J2: Значение_raw | K2: type
B3: Насосное оборудование | G3: formulaColl | K3: enumeration
B4: Компрессоры | G4: var_key | K4: user
B5: Электротовары | G5: var_name | K5: money
B6: Запчасти | G6: var_value | K6: datetime
G7: hide_col | K7: boolean
G8: header_08 | K8: staf
A9: № | B9: Название | C9: Значение | D9: Проверка | E9: Источник информации | F9: Рекомендации | G9: header_last | H9: key | K9: raw
A10: № | B10: Название | C10: Значение | D10: Проверка | E10: Источник информации | F10: Рекомендации | G10: Индификатор поля | H10: HeaderLast
A11: 1 | B11: Номер проекта | C11: PTZ-А-1480 | G11: ufCrm_69EA3A22F3CA9 | H11: НомерПроекта | I11: Да | J11: PTZ-А-1480 | K11: raw
B12: ID_Bitrix | C12: 255 | G12: ID | K12: raw
A13: 0 | B13: URL_Bitrix | G13: URL_Bitrix | K13: raw
B14: Ссылка на таблицу расчета | G14: ufCrm31_1777547556213 | K14: raw
A16: Надо заполнить на основе документации | D16: Проверка | E16: Источник информации: | F16: Рекомендации
A17: 2 | B17: Место поставки товара | C17: Подольск | E17: 1. ТЗ РАЗДЕЛ X. ТРЕБОВАНИЯ К КОЛИЧЕСТВУ, МЕСТУ И СРОКУ (ПЕРИОДИЧНОСТИ) ПОСТАВКИ. 2. Извещение: раздел место исполнения договора или место поставки. 3. Договор: место поставки. 4. Спецификация | G17: ufCrm_69EA3A22B3191 | I17: Да | J17: Подольск | K17: raw
A18: 3 | B18: Срок поставки по договору, календарные дни или точная дата | C18: 30 | D18: =IF(IFERROR(C18/1,0)=0,"Должно быть или число или точная дата, Ошибка","ok") -> ok | E18: 1. ТЗ РАЗДЕЛ X. ТРЕБОВАНИЯ К КОЛИЧЕСТВУ, МЕСТУ И СРОКУ (ПЕРИОДИЧНОСТИ) ПОСТАВКИ. 2. Спецификация (при наличии). 3. Договор (при наличии): либо в разделе ПРЕДМЕТ ДОГОВОРА, либо СРОКИ ПОСТАВКИ, либо в СПЕЦИФИКАЦИИ к договору. 4. Иногда может быть указано в Извещении в разделе предмет договора. | F18: 1. Ищем "срок поставки" в проекте договора или в ТЗ/Спецификации. 2. Если указана конкретная дата ,то вводим ее. 3. Если указан диапазон дат то вводим берем максимальную дату 4. Если указан период : например в течение 40 дней или не более 20 дней с даты заключения договора ,то ставим просто число. 5. Из рабочих (Х) переводим в календарные (Y) с помощью формулы Х=Y/5*7. | G18: ufCrm_69EA3A22BCFF5 | I18: Да | J18: 30 | K18: raw
A19: 4 | B19: Срок доставки, календарные дни | D19: =IF(IFERROR(C19/1,0)=0,"Должно быть или число или точная дата, Ошибка","ok") -> Должно быть или число или точная дата, Ошибка | E19: Надо вычислить самостоятельно. | F19: Смотрим на сайте деловых линий сколько времени занимает доставка из Подольска до заказчика + прибавляем 7 дней | G19: ufCrm_69EA3A22C6588 | I19: Да | K19: raw
A20: 5 | B20: Срок приемки, календарные дни | C20: 7 | D20: =IF(IFERROR(C20/1,0)=0,"Должно быть или число или точная дата, Ошибка","ok") -> ok | E20: Договор раздел ПРИЕМКА ТОВАРА или ПОРЯДОК ПРИЕМКИ. | F20: 1. Изучаем договор или другую документацию по закупке ищем срок приемки товара. 2. Из рабочих (Х) переводим в календарные (Y) с помощью формулы Х=Y/5*7. 3. Если информация отсутствует, то ставим "30". | G20: ufCrm_69EA3A22CFA43 | I20: Да | J20: 7 | K20: raw
A21: 6 | B21: Срок оплаты, календарные дни | C21: 30 | D21: =IF(IFERROR(C21/1,0)=0,"Должно быть или число или точная дата, Ошибка","ok") -> ok | E21: 1. Извещение: Раздел условия оплаты. 2. Договор: раздел порядок оплаты. | F21: 1. Изучаем договор или другую документацию по закупке ищем срок оплаты. 2. Если указана конкретная дата ,то вводим ее. 3. Если указан диапазон дат то вводим берем максимальную дату 4. Если указан период : например в течение 40 дней или не более 20 дней с даты заключения договора ,то ставим просто число. 5. Из рабочих (Х) переводим в календарные (Y) с помощью формулы Х=Y/5*7. 6. Если информация отсутствует, то ставим "30". | G21: ufCrm_69EA3A22D8590 | I21: Да | J21: 30 | K21: raw
A22: 7 | B22: Аванс,% | E22: 1. Извещение: Раздел условия оплаты. 2. Договор: раздел порядок оплаты. | G22: ufCrm_69EA3A220488D | I22: Да | K22: raw
A23: 8 | B23: Аванс, руб | G23: ufCrm_69EA3A221B414 | I23: Да | K23: money
A24: 9 | B24: Неустойка за день просрочки,% | E24: 1. Договор Раздел Ответственность. | G24: ufCrm_69EA3A222390D | I24: Да | K24: raw
A25: 10 | B25: Ограничение неустойки за просрочку | E25: 1. Договор Раздел Ответственность. | G25: ufCrm_69EA3A222B5FD | I25: Да | K25: raw
A26: 11 | B26: Штраф за просрочку от стоимости Товара/договора, % | E26: 1. Договор Раздел Ответственность. | G26: ufCrm_69EA3A22398F7 | I26: Да | K26: enumeration
A27: 12 | B27: Штраф за поставку товара с недостатками от стоимости Товара/договора, % | E27: 1. Договор Раздел Ответственность. | G27: ufCrm_69EA3A2241A6C | I27: Да | K27: enumeration
A28: 13 | B28: Досрочная поставка товара по договору | G28: ufCrm_69EA3A2249278 | I28: Да | K28: enumeration
A29: 14 | B29: Частичная поставка товара по договору | E29: 1. Договор раздел Поставка товара, Условия поставки и т.п. | F29: Если не указано что продукция должна быть поставлена одной партией и в полном объеме то ставим "Да". | G29: ufCrm_69EA3A22507F4 | I29: Да | K29: enumeration
A30: 15 | B30: Частичная оплата товара по договору | E30: Договор. | F30: Если не указано что продукция будет оплачена по факту ПОЛНОЙ поставки то ставим "Да". | G30: ufCrm_69EA3A2257D9F | I30: Да | K30: enumeration
A31: 16 | B31: Поставка по заявке или частями | C31: Нет | G31: ufCrm_69EA3A2232300 | I31: Да | J31: 5329 | K31: enumeration
A32: 17 | B32: Обеспечения заявки, % | E32: Извещение. | G32: ufCrm_69EA3A225EFD0 | I32: Да | K32: raw
A33: 18 | B33: Обеспечения заявки, руб | E33: Извещение. | G33: ufCrm_69EA3A22644AD | I33: Да | K33: money
A34: 19 | B34: Обеспечение ИСПОЛНЕНИЯ договора, % | E34: Извещение./ Проект договора по поиску на слово "Обеспечение" далее искать Обеспечение Исполнения. | G34: ufCrm_69EA3A2269B8F | I34: Да | K34: raw
A35: 20 | B35: Обеспечение ИСПОЛНЕНИЯ договора, руб | E35: Извещение./ Проект договора по поиску на слово "Обеспечение" далее искать Обеспечение Исполнения. | G35: ufCrm_69EA3A226F3CC | I35: Да | K35: money
A36: 21 | B36: Правила приемки | E36: Договор раздел ПРИЕМКА ТОВАРА или ПОРЯДОК ПРИЕМКИ. | G36: ufCrm_69EA3A2274E59 | I36: Да | K36: enumeration
A37: 22 | B37: ЕОС-качество | E37: Договор раздел ПРИЕМКА ТОВАРА или ПОРЯДОК ПРИЕМКИ. | F37: 1. Ищем в договоре ЕОС-качество. 2. Если ЕОС-Качество упоминается, то ставим да,если нет, то нет. | G37: ufCrm_69EA3A227FF23 | I37: Да | K37: enumeration
A38: 23 | B38: Доля импорта | E38: Надо вычислить самостоятельно. | F38: Отношение импортной продукции к общему объему в закупочных ценах.
A39: 24 | B39: Категория поставляемых товаров | G39: ufCrm_69EA3A22E3E95 | I39: Да | K39: enumeration
A40: 25 | B40: НМЦ | D40: =IF(C40<>'1-1 Сбор КП'!K22,"Ошибка проверить попозиционное НМЦ","ok") -> ok | G40: opportunity | I40: Да | J40: 0 | K40: money
A41: 26 | B41: Валюта НМЦ | C41: RUB | D41: =IF(C41="","Необходимо выбрать валюту договора, ошибка","ok") -> ok | G41: currencyId | I41: Да | J41: RUB | K41: raw
...

Sheet 1-0 Товары
C1: header_first
A2: err | B2: err2 | C2: key | D2: Номер | E2: Номенклатура | F2: Характеристики | G2: ЕдИзм | H2: Количевство | I2: НМЦ | J2: НазваниеТовараПоДоговору | K2: ИзготовительТовараПоДоговору | L2: Группа_1_2 | M2: Группа_5_2 | N2: СрокПоставкиПоДоговору
C3: formulaColl | D3: formulaColl | E3: formulaFree | F3: formulaFree | G3: formulaFree | H3: formulaFree | I3: formulaFree | J3: formulaColl | K3: formulaColl | L3: formulaColl | M3: formulaColl | N3: formulaColl
C4: var_key
C5: var_name
C6: var_value
C7: header_07
C8: header_08
C9: header_last
C10: =IFERROR(__xludf.DUMMYFUNCTION("{""ID_Товара""; LAMBDA( doFindRow, doFilter, theWordStart, theCStart, theWordEnd, theCEnd, theDataWord, theData, doFilter(doFindRow(theDataWord,theWordStart,theCStart),doFindRow(theDataWord,theWordEnd,theCEnd),theData) )( LAMBDA(theWords,theWord,theC"&" , VLOOKUP( theWord, BYROW(theWords,LAMBDA(theW,{theW , ROW(theW)})),2,FALSE ) +theC), LAMBDA(bodyStart,bodyEnd,theData, FILTER(theData,bodyStart <= BYROW(theData,lambda(d,ROW(d))) ,BYROW(theData,lambda(d,ROW(d)))<=bodyEnd )), ""№"",1,""@"",-1,'1-1 Сб"&"ор КП'!C1:C31 ,'1-1 Сбор КП'!Z1:Z31 )} "),"ID_Товара") -> ID_Товара | D10: =IFERROR(__xludf.DUMMYFUNCTION("{ {'1-1 Сбор КП'!C1:G1}; {LAMBDA( doFindRow, doFilter, theWordStart, theCStart, theWordEnd, theCEnd, theDataWord, theData, doFilter(doFindRow(theDataWord,theWordStart,theCStart),doFindRow(theDataWord,theWordEnd,theCEnd),theData) )( LAMBDA(theWords,t"&"heWord,theC , VLOOKUP( theWord, BYROW(theWords,LAMBDA(theW,{theW , ROW(theW)})),2,FALSE ) +theC), LAMBDA(bodyStart,bodyEnd,theData, FILTER(theData,bodyStart <= BYROW(theData,lambda(d,ROW(d))) ,BYROW(theData,lambda(d,ROW(d)))<=bodyEnd )), ""№"",1,""@"""&",-1,'1-1 Сбор КП'!C1:C31 ,'1-1 Сбор КП'!C1:G31 )} }"),"№") -> № | E10: =IFERROR(__xludf.DUMMYFUNCTION("""COMPUTED_VALUE"""),"Номенклатура") -> Номенклатура | F10: =IFERROR(__xludf.DUMMYFUNCTION("""COMPUTED_VALUE"""),"Характеристики") -> Характеристики | G10: =IFERROR(__xludf.DUMMYFUNCTION("""COMPUTED_VALUE"""),"Ед. Изм") -> Ед. Изм | H10: =IFERROR(__xludf.DUMMYFUNCTION("""COMPUTED_VALUE"""),"Кол-во") -> Кол-во | I10: =IFERROR(__xludf.DUMMYFUNCTION("{ {'1-1 Сбор КП'!K1}; {LAMBDA( doFindRow, doFilter, theWordStart, theCStart, theWordEnd, theCEnd, theDataWord, theData, doFilter(doFindRow(theDataWord,theWordStart,theCStart),doFindRow(theDataWord,theWordEnd,theCEnd),theData) )( LAMBDA(theWords,theW"&"ord,theC , VLOOKUP( theWord, BYROW(theWords,LAMBDA(theW,{theW , ROW(theW)})),2,FALSE ) +theC), LAMBDA(bodyStart,bodyEnd,theData, FILTER(theData,bodyStart <= BYROW(theData,lambda(d,ROW(d))) ,BYROW(theData,lambda(d,ROW(d)))<=bodyEnd )), ""№"",1,""@"",-1"&",'1-1 Сбор КП'!C1:C31 ,'1-1 Сбор КП'!K1:K31 )} }"),"НМЦ") -> НМЦ | J10: {=IF(E10:E313<>"",IFERROR(VLOOKUP(E10:E313,{'5-1 Сбор КП Закупки'!E10:E313,'5-1 Сбор КП Закупки'!F10:F313},2,FALSE) ,),)} -> Название товара по договору | K10: {=IF(E10:E313<>"",IFERROR(VLOOKUP(E10:E313,{'5-1 Сбор КП Закупки'!E10:E313,'5-1 Сбор КП Закупки'!G10:G313},2,FALSE) ,),)} -> Изготовитель товара по договору | L10: =IFERROR(__xludf.DUMMYFUNCTION("BYROW({ {'1-1 Сбор КП'!O1}; {LAMBDA( doFindRow, doFilter, theWordStart, theCStart, theWordEnd, theCEnd, theDataWord, theData, doFilter(doFindRow(theDataWord,theWordStart,theCStart),doFindRow(theDataWord,theWordEnd,theCEnd),theData) )( LAMBDA(theWord"&"s,theWord,theC , VLOOKUP( theWord, BYROW(theWords,LAMBDA(theW,{theW , ROW(theW)})),2,FALSE ) +theC), LAMBDA(bodyStart,bodyEnd,theData, FILTER(theData,bodyStart <= BYROW(theData,lambda(d,ROW(d))) ,BYROW(theData,lambda(d,ROW(d)))<=bodyEnd )), ""№"",1,"""&"@"",-1,'1-1 Сбор КП'!C1:C31 ,'1-1 Сбор КП'!O1:O31 )} },LAMBDA(theG,IFERROR(theG,)))"),"Группа") -> Группа | M10: {={"Группа";LAMBDA(doFind,theIds,theData, doFind(theIds,theData) )( LAMBDA(theIds,theData, BYROW(theIds,LAMBDA(ti,IF(ti<>"", IFERROR(VLOOKUP(ti,theData,2,0),),)))), '1-0 Товары'!C11:C313, {'5-2 Запросы КП Закупки'!C11:C313,'5-2 Запросы КП Закупки'!N11:N313} )}} -> Группа | N10: =IFERROR(__xludf.DUMMYFUNCTION("{ {'1-1 Сбор КП'!N1}; {LAMBDA( doFindRow, doFilter, theWordStart, theCStart, theWordEnd, theCEnd, theDataWord, theData, doFilter(doFindRow(theDataWord,theWordStart,theCStart),doFindRow(theDataWord,theWordEnd,theCEnd),theData) )( LAMBDA(theWords,theW"&"ord,theC , VLOOKUP( theWord, BYROW(theWords,LAMBDA(theW,{theW , ROW(theW)})),2,FALSE ) +theC), LAMBDA(bodyStart,bodyEnd,theData, FILTER(theData,bodyStart <= BYROW(theData,lambda(d,ROW(d))) ,BYROW(theData,lambda(d,ROW(d)))<=bodyEnd )), ""№"",1,""@"",-1"&",'1-1 Сбор КП'!C1:C31 ,'1-1 Сбор КП'!N1:N31 )} }"),"Срок поставки по договору") -> Срок поставки по договору | O10: =IFERROR(__xludf.DUMMYFUNCTION("{ {'1-1 Сбор КП'!L1}; {LAMBDA( doFindRow, doFilter, theWordStart, theCStart, theWordEnd, theCEnd, theDataWord, theData, doFilter(doFindRow(theDataWord,theWordStart,theCStart),doFindRow(theDataWord,theWordEnd,theCEnd),theData) )( LAMBDA(theWords,theW"&"ord,theC , VLOOKUP( theWord, BYROW(theWords,LAMBDA(theW,{theW , ROW(theW)})),2,FALSE ) +theC), LAMBDA(bodyStart,bodyEnd,theData, FILTER(theData,bodyStart <= BYROW(theData,lambda(d,ROW(d))) ,BYROW(theData,lambda(d,ROW(d)))<=bodyEnd )), ""№"",1,""@"",-1"&",'1-1 Сбор КП'!C1:C31 ,'1-1 Сбор КП'!L1:L31 )} }"),"Нац режим 1875") -> Нац режим 1875 | P10: =IFERROR(__xludf.DUMMYFUNCTION("{ {'1-1 Сбор КП'!M1}; {LAMBDA( doFindRow, doFilter, theWordStart, theCStart, theWordEnd, theCEnd, theDataWord, theData, doFilter(doFindRow(theDataWord,theWordStart,theCStart),doFindRow(theDataWord,theWordEnd,theCEnd),theData) )( LAMBDA(theWords,theW"&"ord,theC , VLOOKUP( theWord, BYROW(theWords,LAMBDA(theW,{theW , ROW(theW)})),2,FALSE ) +theC), LAMBDA(bodyStart,bodyEnd,theData, FILTER(theData,bodyStart <= BYROW(theData,lambda(d,ROW(d))) ,BYROW(theData,lambda(d,ROW(d)))<=bodyEnd )), ""№"",1,""@"",-1"&",'1-1 Сбор КП'!C1:C31 ,'1-1 Сбор КП'!M1:M31 )} }"),"Код ОКПД 2") -> Код ОКПД 2
C11: =IFERROR(__xludf.DUMMYFUNCTION("""COMPUTED_VALUE"""),"ID_T001") -> ID_T001 | D11: =IFERROR(__xludf.DUMMYFUNCTION("""COMPUTED_VALUE"""),"1") -> 1 | E11: =IFERROR(__xludf.DUMMYFUNCTION("""COMPUTED_VALUE"""),"Масляный фильтр - Артикул 89781969 ESG-315 зав.№ F010451") -> Масляный фильтр - Артикул 89781969 ESG-315 зав.№ F010451 | F11: =IFERROR(__xludf.DUMMYFUNCTION("""COMPUTED_VALUE""")," ESG-315 зав. № F01045") -> ESG-315 зав. № F01045 | G11: =IFERROR(__xludf.DUMMYFUNCTION("""COMPUTED_VALUE"""),"шт.") -> шт. | H11: =IFERROR(__xludf.DUMMYFUNCTION("""COMPUTED_VALUE"""),3.0) -> 3
C12: =IFERROR(__xludf.DUMMYFUNCTION("""COMPUTED_VALUE"""),"ID_T002") -> ID_T002 | D12: =IFERROR(__xludf.DUMMYFUNCTION("""COMPUTED_VALUE"""),"2") -> 2 | E12: =IFERROR(__xludf.DUMMYFUNCTION("""COMPUTED_VALUE"""),"Масляный фильтр - Артикул 85062259") -> Масляный фильтр - Артикул 85062259 | F12: =IFERROR(__xludf.DUMMYFUNCTION("""COMPUTED_VALUE"""),"ESG-315 зав.№ 17030008 VS-250; ESM-200") -> ESG-315 зав.№ 17030008 VS-250; ESM-200 | G12: =IFERROR(__xludf.DUMMYFUNCTION("""COMPUTED_VALUE"""),"шт.") -> шт. | H12: =IFERROR(__xludf.DUMMYFUNCTION("""COMPUTED_VALUE"""),6.0) -> 6
C13: =IFERROR(__xludf.DUMMYFUNCTION("""COMPUTED_VALUE"""),"ID_T003") -> ID_T003 | D13: =IFERROR(__xludf.DUMMYFUNCTION("""COMPUTED_VALUE"""),"3") -> 3 | E13: =IFERROR(__xludf.DUMMYFUNCTION("""COMPUTED_VALUE"""),"Воздушный фильтр - Артикул 85067179 ") -> Воздушный фильтр - Артикул 85067179 | F13: =IFERROR(__xludf.DUMMYFUNCTION("""COMPUTED_VALUE"""),"ESG-315 зав.№ F010451; ESG-315 зав.№ 17030008 VS-250; ESM-200; «Gardner Denver»") -> ESG-315 зав.№ F010451; ESG-315 зав.№ 17030008 VS-250; ESM-200; «Gardner Denver» | G13: =IFERROR(__xludf.DUMMYFUNCTION("""COMPUTED_VALUE"""),"шт.") -> шт. | H13: =IFERROR(__xludf.DUMMYFUNCTION("""COMPUTED_VALUE"""),16.0) -> 16
C14: =IFERROR(__xludf.DUMMYFUNCTION("""COMPUTED_VALUE"""),"ID_T004") -> ID_T004 | D14: =IFERROR(__xludf.DUMMYFUNCTION("""COMPUTED_VALUE"""),"4") -> 4 | E14: =IFERROR(__xludf.DUMMYFUNCTION("""COMPUTED_VALUE"""),"Термостат в сборе ESM-200; «Gardner Denver»") -> Термостат в сборе ESM-200; «Gardner Denver» | F14: =IFERROR(__xludf.DUMMYFUNCTION("""COMPUTED_VALUE"""),"ESM-200; «Gardner Denver»") -> ESM-200; «Gardner Denver» | G14: =IFERROR(__xludf.DUMMYFUNCTION("""COMPUTED_VALUE"""),"шт.") -> шт. | H14: =IFERROR(__xludf.DUMMYFUNCTION("""COMPUTED_VALUE"""),2.0) -> 2
C15: =IFERROR(__xludf.DUMMYFUNCTION("""COMPUTED_VALUE"""),"ID_T005") -> ID_T005 | D15: =IFERROR(__xludf.DUMMYFUNCTION("""COMPUTED_VALUE"""),"5") -> 5 | E15: =IFERROR(__xludf.DUMMYFUNCTION("""COMPUTED_VALUE"""),"Масляный сепаратор Артикул 03498328") -> Масляный сепаратор Артикул 03498328 | F15: =IFERROR(__xludf.DUMMYFUNCTION("""COMPUTED_VALUE""")," ESS-18 «Gardner Denver»") -> ESS-18 «Gardner Denver» | G15: =IFERROR(__xludf.DUMMYFUNCTION("""COMPUTED_VALUE"""),"шт.") -> шт. | H15: =IFERROR(__xludf.DUMMYFUNCTION("""COMPUTED_VALUE"""),3.0) -> 3
C16: =IFERROR(__xludf.DUMMYFUNCTION("""COMPUTED_VALUE"""),"ID_T006") -> ID_T006 | D16: =IFERROR(__xludf.DUMMYFUNCTION("""COMPUTED_VALUE"""),"6") -> 6 | E16: =IFERROR(__xludf.DUMMYFUNCTION("""COMPUTED_VALUE"""),"Масляный фильтр Артикул 89675429") -> Масляный фильтр Артикул 89675429 | F16: =IFERROR(__xludf.DUMMYFUNCTION("""COMPUTED_VALUE""")," ESS-18 «Gardner Denver»") -> ESS-18 «Gardner Denver» | G16: =IFERROR(__xludf.DUMMYFUNCTION("""COMPUTED_VALUE"""),"шт.") -> шт. | H16: =IFERROR(__xludf.DUMMYFUNCTION("""COMPUTED_VALUE"""),3.0) -> 3
C17: =IFERROR(__xludf.DUMMYFUNCTION("""COMPUTED_VALUE"""),"ID_T007") -> ID_T007 | D17: =IFERROR(__xludf.DUMMYFUNCTION("""COMPUTED_VALUE"""),"7") -> 7 | E17: =IFERROR(__xludf.DUMMYFUNCTION("""COMPUTED_VALUE"""),"Воздушный фильтр - Артикул 81166609") -> Воздушный фильтр - Артикул 81166609 | F17: =IFERROR(__xludf.DUMMYFUNCTION("""COMPUTED_VALUE""")," ESS-18 «Gardner Denver»") -> ESS-18 «Gardner Denver» | G17: =IFERROR(__xludf.DUMMYFUNCTION("""COMPUTED_VALUE"""),"шт.") -> шт. | H17: =IFERROR(__xludf.DUMMYFUNCTION("""COMPUTED_VALUE"""),3.0) -> 3
C18: =IFERROR(__xludf.DUMMYFUNCTION("""COMPUTED_VALUE"""),"ID_T008") -> ID_T008 | D18: =IFERROR(__xludf.DUMMYFUNCTION("""COMPUTED_VALUE"""),"8") -> 8 | E18: =IFERROR(__xludf.DUMMYFUNCTION("""COMPUTED_VALUE"""),"Сервисный набор арт. 2906020000 ") -> Сервисный набор арт. 2906020000 | F18: =IFERROR(__xludf.DUMMYFUNCTION("""COMPUTED_VALUE"""),"GA 200 зав. № APF133999; GA 250 зав. № APF133914; GA 250 зав. № APF 133915 «Atlas Copco»") -> GA 200 зав. № APF133999; GA 250 зав. № APF133914; GA 250 зав. № APF 133915 «Atlas Copco» | G18: =IFERROR(__xludf.DUMMYFUNCTION("""COMPUTED_VALUE"""),"шт.") -> шт. | H18: =IFERROR(__xludf.DUMMYFUNCTION("""COMPUTED_VALUE"""),3.0) -> 3
C19: =IFERROR(__xludf.DUMMYFUNCTION("""COMPUTED_VALUE"""),"ID_T009") -> ID_T009 | D19: =IFERROR(__xludf.DUMMYFUNCTION("""COMPUTED_VALUE"""),"9") -> 9 | E19: =IFERROR(__xludf.DUMMYFUNCTION("""COMPUTED_VALUE"""),"Сервисный набор 8000 ч. арт. 2906075700") -> Сервисный набор 8000 ч. арт. 2906075700 | F19: =IFERROR(__xludf.DUMMYFUNCTION("""COMPUTED_VALUE"""),"GA 200 зав. № APF133999; GA 250 зав. № APF133914; GA 250 зав. № APF 133915 «Atlas Copco»") -> GA 200 зав. № APF133999; GA 250 зав. № APF133914; GA 250 зав. № APF 133915 «Atlas Copco» | G19: =IFERROR(__xludf.DUMMYFUNCTION("""COMPUTED_VALUE"""),"шт.") -> шт. | H19: =IFERROR(__xludf.DUMMYFUNCTION("""COMPUTED_VALUE"""),3.0) -> 3
C20: =IFERROR(__xludf.DUMMYFUNCTION("""COMPUTED_VALUE"""),"ID_T010") -> ID_T010 | D20: =IFERROR(__xludf.DUMMYFUNCTION("""COMPUTED_VALUE"""),"10") -> 10 | E20: =IFERROR(__xludf.DUMMYFUNCTION("""COMPUTED_VALUE"""),"Масляный сепаратор ") -> Масляный сепаратор | F20: =IFERROR(__xludf.DUMMYFUNCTION("""COMPUTED_VALUE"""),"«Dalgakiran» Inversys +315 зав. №VD 4037, зав. № VD 6420.") -> «Dalgakiran» Inversys +315 зав. №VD 4037, зав. № VD 6420. | G20: =IFERROR(__xludf.DUMMYFUNCTION("""COMPUTED_VALUE"""),"шт.") -> шт. | H20: =IFERROR(__xludf.DUMMYFUNCTION("""COMPUTED_VALUE"""),3.0) -> 3
C21: =IFERROR(__xludf.DUMMYFUNCTION("""COMPUTED_VALUE"""),"ID_T011") -> ID_T011 | D21: =IFERROR(__xludf.DUMMYFUNCTION("""COMPUTED_VALUE"""),"11") -> 11 | E21: =IFERROR(__xludf.DUMMYFUNCTION("""COMPUTED_VALUE"""),"Воздушный фильтр") -> Воздушный фильтр | F21: =IFERROR(__xludf.DUMMYFUNCTION("""COMPUTED_VALUE"""),"«Dalgakiran» Inversys +315 зав. №VD 4037, зав. № VD 6420.") -> «Dalgakiran» Inversys +315 зав. №VD 4037, зав. № VD 6420. | G21: =IFERROR(__xludf.DUMMYFUNCTION("""COMPUTED_VALUE"""),"шт.") -> шт. | H21: =IFERROR(__xludf.DUMMYFUNCTION("""COMPUTED_VALUE"""),6.0) -> 6
C22: =IFERROR(__xludf.DUMMYFUNCTION("""COMPUTED_VALUE"""),"ID_T012") -> ID_T012 | D22: =IFERROR(__xludf.DUMMYFUNCTION("""COMPUTED_VALUE"""),"12") -> 12 | E22: =IFERROR(__xludf.DUMMYFUNCTION("""COMPUTED_VALUE"""),"Масляный фильтр") -> Масляный фильтр | F22: =IFERROR(__xludf.DUMMYFUNCTION("""COMPUTED_VALUE"""),"«Dalgakiran» Inversys +315 зав. №VD 4037, зав. № VD 6420.") -> «Dalgakiran» Inversys +315 зав. №VD 4037, зав. № VD 6420. | G22: =IFERROR(__xludf.DUMMYFUNCTION("""COMPUTED_VALUE"""),"шт.") -> шт. | H22: =IFERROR(__xludf.DUMMYFUNCTION("""COMPUTED_VALUE"""),6.0) -> 6
C23: =IFERROR(__xludf.DUMMYFUNCTION("""COMPUTED_VALUE"""),"ID_T013") -> ID_T013 | D23: =IFERROR(__xludf.DUMMYFUNCTION("""COMPUTED_VALUE"""),"13") -> 13 | E23: =IFERROR(__xludf.DUMMYFUNCTION("""COMPUTED_VALUE"""),"Масляный сепаратор DS 3084 ") -> Масляный сепаратор DS 3084 | F23: =IFERROR(__xludf.DUMMYFUNCTION("""COMPUTED_VALUE"""),"BB-50/8 ВУЗ АО «НПАО «ВНИИ компрессормаш»") -> BB-50/8 ВУЗ АО «НПАО «ВНИИ компрессормаш» | G23: =IFERROR(__xludf.DUMMYFUNCTION("""COMPUTED_VALUE"""),"шт.") -> шт. | H23: =IFERROR(__xludf.DUMMYFUNCTION("""COMPUTED_VALUE"""),2.0) -> 2
C24: =IFERROR(__xludf.DUMMYFUNCTION("""COMPUTED_VALUE"""),"ID_T014") -> ID_T014 | D24: =IFERROR(__xludf.DUMMYFUNCTION("""COMPUTED_VALUE"""),"14") -> 14 | E24: =IFERROR(__xludf.DUMMYFUNCTION("""COMPUTED_VALUE"""),"Воздушный фильтр ЛААЗ ЭФВ 721.1109560 (7405. 1109560)") -> Воздушный фильтр ЛААЗ ЭФВ 721.1109560 (7405. 1109560) | F24: =IFERROR(__xludf.DUMMYFUNCTION("""COMPUTED_VALUE"""),"BB-50/8 ВУЗ АО «НПАО «ВНИИ компрессормаш»") -> BB-50/8 ВУЗ АО «НПАО «ВНИИ компрессормаш» | G24: =IFERROR(__xludf.DUMMYFUNCTION("""COMPUTED_VALUE"""),"шт.") -> шт. | H24: =IFERROR(__xludf.DUMMYFUNCTION("""COMPUTED_VALUE"""),4.0) -> 4
C25: =IFERROR(__xludf.DUMMYFUNCTION("""COMPUTED_VALUE"""),"ID_T015") -> ID_T015 | D25: =IFERROR(__xludf.DUMMYFUNCTION("""COMPUTED_VALUE"""),"15") -> 15 | E25: =IFERROR(__xludf.DUMMYFUNCTION("""COMPUTED_VALUE"""),"Масляный фильтр W13145/3") -> Масляный фильтр W13145/3 | F25: =IFERROR(__xludf.DUMMYFUNCTION("""COMPUTED_VALUE"""),"BB-50/8 ВУЗ АО «НПАО «ВНИИ компрессормаш»") -> BB-50/8 ВУЗ АО «НПАО «ВНИИ компрессормаш» | G25: =IFERROR(__xludf.DUMMYFUNCTION("""COMPUTED_VALUE"""),"шт.") -> шт. | H25: =IFERROR(__xludf.DUMMYFUNCTION("""COMPUTED_VALUE"""),4.0) -> 4
C26: =IFERROR(__xludf.DUMMYFUNCTION("""COMPUTED_VALUE"""),"ID_T016") -> ID_T016 | D26: =IFERROR(__xludf.DUMMYFUNCTION("""COMPUTED_VALUE"""),"16") -> 16
C27: =IFERROR(__xludf.DUMMYFUNCTION("""COMPUTED_VALUE"""),"ID_T017") -> ID_T017 | D27: =IFERROR(__xludf.DUMMYFUNCTION("""COMPUTED_VALUE"""),"17") -> 17
C28: =IFERROR(__xludf.DUMMYFUNCTION("""COMPUTED_VALUE"""),"ID_T018") -> ID_T018 | D28: =IFERROR(__xludf.DUMMYFUNCTION("""COMPUTED_VALUE"""),"18") -> 18
C29: =IFERROR(__xludf.DUMMYFUNCTION("""COMPUTED_VALUE"""),"ID_T019") -> ID_T019 | D29: =IFERROR(__xludf.DUMMYFUNCTION("""COMPUTED_VALUE"""),"19") -> 19
C30: =IFERROR(__xludf.DUMMYFUNCTION("""COMPUTED_VALUE"""),"ID_T020") -> ID_T020 | D30: =IFERROR(__xludf.DUMMYFUNCTION("""COMPUTED_VALUE"""),"20") -> 20

Sheet 1-1 Сбор КП
C1: № | D1: Номенклатура | E1: Характеристики | F1: Ед. Изм | G1: Кол-во | H1: Цена | I1: Итого | J1: Предложений | K1: НМЦ | L1: Нац режим 1875 | M1: Код ОКПД 2 | N1: Срок поставки по договору | O1: {={"Группа";LAMBDA(theNames,theData,BYROW(theNames,LAMBDA(tn,IFERROR(VLOOKUP(tn,theData,2,0),))))(C2:C21,{'1-2 Запросы по товарным группам'!D:D,'1-2 Запросы по товарным группам'!O:O})}} -> Группа | P1: =IFERROR(__xludf.DUMMYFUNCTION("{{""Доля ответов"",""Предложение"",""Писем""};let( _t_em_map , let( _t_gr, '1-2 Запросы по товарным группам'!$O11:$O311, _t_nm, '1-2 Запросы по товарным группам'!$P11:$P311, _t_em, '1-2 Запросы по товарным группам'!$AA11:JI$311, do_sm, LAMBDA"&"(em_mp, BYROW(em_mp,LAMBDA(e_ar,COUNTA(e_ar)))), QUERY( {{""Группа"" , ""Кол-во""};{Map(_t_gr,_t_nm,do_sm(_t_em),LAMBDA(g,n,s,IF(n=2,{g,s},{"""",""""})) )}},""Select * Where Col1 is not null"") ), _t_ot_mp , BYROW('1-1 Сбор КП'!$AA2:$HS30, LAMBDA(r,"&" IFERROR(COUNTA( FILTER(r,MOD( COLUMN(r),3)=0 ) ),) )), _t_mp_stat_tov, MAP('1-1 Сбор КП'!$Z2:$Z30,'1-1 Сбор КП'!$D2:$D30,_t_ot_mp,'1-1 Сбор КП'!$O2:$O30, LAMBDA(z,t,r,g, {z,IF(t<>"""",IFERROR( r/VLOOKUP(g,_t_em_map,2,FALSE) ,),),IF(t<>"""",r,),IFERROR( V"&"LOOKUP(g,_t_em_map,2,FALSE) ,)})), _t_mp_stat_itog, LAMBDA(_t, let ( _t_dolya, LAMBDA(_a,SUM(_a)/COUNT(_a))(INDEX( _t,,2)) ,_t_predl, LAMBDA(_a,SUM(_a))(INDEX( _t,,3)) , {""@"",_t_dolya , _t_predl , "" ""}))(_t_mp_stat_tov), _t_raw_rez,{_t_mp_stat_tov;_t_"&"mp_stat_itog}, _t_ord, LET( _t_nrs, '1-1 Сбор КП'!$C$1:$C30, _t_ids, '1-1 Сбор КП'!$Z$1:$Z30, _t_fr, MATCH(""№"", _t_nrs, 0) + 1, _t_to, MATCH(""@"", _t_nrs, 0) - 1, {INDEX(_t_ids, _t_fr,1):INDEX(_t_ids, _t_to,1); ""@""}), rez,Byrow(_t_ord,LAMB"&"DA(o, ARRAYFORMULA( IFERROR(VLOOKUP(o,_t_raw_rez,{2,3,4},FALSE) , ) ))), rez )}"),"Доля ответов") -> Доля ответов | Q1: =IFERROR(__xludf.DUMMYFUNCTION("""COMPUTED_VALUE"""),"Предложение") -> Предложение | R1: =IFERROR(__xludf.DUMMYFUNCTION("""COMPUTED_VALUE"""),"Писем") -> Писем | S1: свободные | T1: свободные | U1: свободные | V1: свободные | W1: свободные | X1: свободные | Y1: свободные | Z1: Цены Начало | AA1: amkomplekt@mail.ru | AD1: sales@noemi-parts.ru | AG1: aa@kentek.ru | AJ1: dg@air-part.ru | AM1: 104@pnevmotek.com | AP1: vkorolev@rutector.ru | AS1: bmd@melcom-ural.ru | AV1: utkm@mail.ru | AY1: engelsfilter@mail.ru | BB1: rt@air-part.ru | BE1: order@techfil.ru | BH1: ca@air-part.ru (1) | BK1: ca@air-part.ru (2) | BN1: m.rulev@a-ac.ru | BQ1: zap-premium@mail.ru | BT1: otgruzka@proftool.ru | BW1: kononov@indust-group.ru | BZ1: r.staroverov@evlart.ru | CC1: e.omelyusik@evlart.ru | CF1: sale@dlv-rnd.ru | CI1: davidov@pressair.ru | HS1: Цены Конец | HT1: 1 цена | HU1: поставщик | HV1: 2 цена | HW1: поставщик | HX1: 3 цена | HY1: поставщик | ID1: Комментарий | IE1: Лучшие цены | IF1: CommentBlokStart | IL1: CommentBlokEnd | IQ1: КомментарийЭксперта | IR1: ТопЭксперта | IS1: CommentExpertBlokStart | JF1: CommentExpertBlokEnd
A2: Доллар | B2: ='4-1 Расчет рентабельности КП'!AJ43 -> #REF! | C2: 1 | D2: Масляный фильтр - Артикул 89781969 ESG-315 зав.№ F010451 | E2: ESG-315 зав. № F01045 | F2: шт. | G2: 3 | H2: 5 450,00 6 433,68 | I2: 16 350,00 19 301,04 | J2: 7, из них аналог 4 | Q2: =IFERROR(__xludf.DUMMYFUNCTION("""COMPUTED_VALUE"""),7.0) -> 7 | Z2: ID_T001 | BE2: 6900 | BF2: 5 рд | BG2: Масляный фильтр 89781969 [ Аналог SH/O8186 ] | BH2: 19500 | BI2: 18 нед | BJ2: Масляный фильтр - Артикул 89781969 (оригинал) | BK2: 8600 | BL2: нал | BM2: Масляный фильтр - Артикул 89781969 (аналог) | BQ2: 6250 | BR2: 7 рд | BS2: Фильтр масляный 89781969 аналог | BZ2: 6433.68 | CA2: нал | CB2: Масляный фильтр - Артикул 89781969 ESG-315 — Аналог | CF2: =814.69*B3 -> #REF! | CG2: 5 д | CH2: Масляный фильтр (арт. 85062259) | CI2: 5450 | CJ2: 5 рд | CK2: Масляный фильтр 89781969 = SH8186 | HT2: =IFERROR(SMALL($R2:$HS2,VALUE(LEFT(HT$1,1))),"") | HU2: =IFERROR(OFFSET($AA$1,0,MATCH(HT2,$AA2:$HS2,0)),"") | HV2: =IFERROR(SMALL($AA2:$HS2,VALUE(LEFT(HV$1,1))),"") | HW2: =IFERROR(OFFSET($A$1,0,MATCH(HV2,$AA2:$HS2,0)),"") | HX2: =IFERROR(SMALL($AA2:$HS2,VALUE(LEFT(HX$1,1))),"") | HY2: =IFERROR(OFFSET($AA$1,0,MATCH(HX2,$AA2:$HS2,0)),"") | ID2: =IFERROR(__xludf.DUMMYFUNCTION(" IFERROR( TEXTJOIN(""|||"",FALSE , ARRAY_CONSTRAIN( SORT( ARRAYFORMULA(Split(TRANSPOSE (Split(TEXTJOIN(""|||"",TRUE,'1-1 Сбор КП'!$IF2:$IL2),""|||"",FALSE,FALSE) ),""|"",FALSE,FALSE)),3,FALSE ),100,2) ) ,)"),"") | IE2: =IFERROR(__xludf.DUMMYFUNCTION("LAMBDA(cc,тело,комент, комЭкс, порядок,показ, BYROW(тело, LAMBDA(r, TEXTJOIN(""|||"",FALSE,ARRAY_CONSTRAIN( Query( TRANSPOSE( { {ARRAYFORMULA( FILTER( ADDRESS(ROW(r), COLUMN(r) ), MOD(COLUMN(r)-cc,3)=0))}; {ARRAYFORMULA( FILTER( ADDRESS(1, COLUMN(r) ), MO"&"D(COLUMN(r)-cc,3)=0))}; {ARRAYFORMULA( IFERROR(VLOOKUP( FILTER( ADDRESS(1, COLUMN(r) ), MOD(COLUMN(r)-cc,3)=0), { TRANSPOSE (FILTER( {SPLIT(INDEX(комент,1,0),""|||"",FALSE,FALSE)}, ARRAYFORMULA( ISODD({SEQUENCE(1, COLUMNS(SPLIT(INDEX(комент,1,0),""|||"&""",FALSE,FALSE) ), 1, 1)})))) , TRANSPOSE (FILTER( {SPLIT(INDEX(комент,1,0),""|||"",FALSE,FALSE)}, ARRAYFORMULA( ISEVEN({SEQUENCE(1, COLUMNS( SPLIT(INDEX(комент,1,0),""|||"",FALSE,FALSE) ), 1, 1)}))))} ,2,0 ),""""))}; {ARRAYFORMULA( FILTER( ADDRESS(RO"&"W(r), COLUMN(r) ), MOD(COLUMN(r)-cc,3)=1))}; {ARRAYFORMULA( Lambda(f,m,""Подходит: ""& IFERROR( VLOOKUP( f, комЭкс, 4,0 ),""-?"")&"", ""& m&"" ""&IFERROR(VLOOKUP( f, комЭкс, 2,0 ),)&"" ""&IFERROR(VLOOKUP( f, комЭкс, 3,0 ),) ) ( FILTER( ADDRESS(1, COLUM"&"N(r) ), MOD(COLUMN(r)-cc,3)=0), FILTER( r, MOD(COLUMN(r)-cc,3)=2) ) ) }; {ARRAYFORMULA( FILTER( r, MOD(COLUMN(r)-cc,3)=0))}; BYCOL({ARRAYFORMULA( FILTER( ""'1-1 Сбор КП'!""&""R1C""&COLUMN(r) , MOD(COLUMN(r)-cc,3)=0))},LAMBDA(aa, LAMBDA(a,ifs ( IFERR"&"OR(FIND(""(♠)"",a),0)<>0,IFERROR( VLOOKUP(""♠"",порядок,2,FALSE),5), IFERROR(FIND(""(♦️)"",a),0)<>0,IFERROR( VLOOKUP(""♦️"",порядок,2,FALSE),5), IFERROR(FIND(""(♣️)"",a),0)<>0,IFERROR( VLOOKUP(""♣️"",порядок,2,FALSE),5), IFERROR(FIND(""(♥️)"",a),0)<>0,IFE"&"RROR( VLOOKUP(""♥️"",порядок,2,FALSE),5), TRUE,IFERROR( VLOOKUP(""-"",порядок,2,FALSE),5) ))(INDIRECT( aa,FALSE) ) )); BYCOL({ARRAYFORMULA( FILTER( ""'1-1 Сбор КП'!""&""R1C""&COLUMN(r) , MOD(COLUMN(r)-cc,3)=0))},LAMBDA(aa, LAMBDA(a,ifs ( IFERROR(FIND"&"(""(♠)"",a),0)<>0,IFERROR( VLOOKUP(""♠"",показ,2,FALSE),TRUE), IFERROR(FIND(""(♦️)"",a),0)<>0,IFERROR( VLOOKUP(""♦️"",показ,2,FALSE),TRUE), IFERROR(FIND(""(♣️)"",a),0)<>0,IFERROR( VLOOKUP(""♣️"",показ,2,FALSE),TRUE), IFERROR(FIND(""(♥️)"",a),0)<>0,IFERROR"&"( VLOOKUP(""♥️"",показ,2,FALSE),TRUE), TRUE,IFERROR( VLOOKUP(""-"",показ,2,FALSE),TRUE) ))(INDIRECT( aa,FALSE) ) )) }),""Select * Where Col6 is not null and Col8=true Order by Col7, Col6"",0),7,5)) ) ) ) ( COLUMN('1-1 Сбор КП'!$AA2), '1-1 Сбор КП'!$A"&"A2:$HS2, '1-1 Сбор КП'!$ID2, BYROW( TRANSPOSE(Split('1-1 Сбор КП'!$IQ2,""|||"",FALSE)),LAMBDA(rc,Split(rc,""📎"",FALSE,FALSE))), {'3-3 Выбор поставщиков'!$AB$24:$AB$28 , '3-3 Выбор поставщиков'!$AF$24:$AF$28}, {'3-3 Выбор поставщиков'!$AB$24:$AB$28 ,"&" '3-3 Выбор поставщиков'!$AD$24:$AD$28} )"),"$CI$2|||$CI$1||||||$CJ$2|||Подходит: Осн поставщик, Масляный фильтр 89781969 = SH8186 |||$BQ$2|||$BQ$1||||||$BR$2|||Подходит: Да, Фильтр масляный 89781969 аналог |||$BZ$2|||$BZ$1||||||$CA$2|||Подходит: -?, Масляный фильтр - Артикул 89781969 ESG-315 — "&"Аналог |||$BE$2|||$BE$1||||||$BF$2|||Подходит: Да, Масляный фильтр 89781969 [ Аналог SH/O8186 ] |||$BK$2|||$BK$1||||||$BL$2|||Подходит: -?, Масляный фильтр - Артикул 89781969 (аналог) |||$BH$2|||$BH$1||||||$BI$2|||Подходит: -?, Масляный фильтр - Артик"&"ул 89781969 (оригинал) ") -> $CI$2|||$CI$1||||||$CJ$2|||Подходит: Осн поставщик, Масляный фильтр 89781969 = SH8186 |||$BQ$2|||$BQ$1||||||$BR$2|||Подходит: Да, Фильтр масляный 89781969 аналог |||$BZ$2|||$BZ$1||||||$CA$2|||Подходит: -?, Масляный фильтр - Артикул 89781969 ESG-315 — Аналог |||$BE$2|||$BE$1||||||$BF$2|||Подходит: Да, Масляный фильтр 89781969 [ Аналог SH/O8186 ] |||$BK$2|||$BK$1||||||$BL$2|||Подходит: -?, Масляный фильтр - Артикул 89781969 (аналог) |||$BH$2|||$BH$1||||||$BI$2|||Подходит: -?, Масляный фильтр - Артикул 89781969 (оригинал) | IQ2: =IFERROR(__xludf.DUMMYFUNCTION(" IFERROR( TEXTJOIN(""|||"",true , BYROW( ARRAY_CONSTRAIN( SORT( ARRAYFORMULA( Split( TRANSPOSE ( Split(TEXTJOIN(""|||"", TRUE, '1-1 Сбор КП'!$IS2:$JF2) ,""|||"",FALSE,FALSE) ),""📎"",FALSE,FALSE"&")),5,FALSE ),100,4) ,LAMBDA(r,TEXTJOIN(""📎"",FALSE ,r)) ) ,))"),"$BQ$1📎📎📎Да|||$CI$1📎📎📎Осн поставщик|||$CI$1📎📎📎Осн поставщик|||$BE$1📎📎📎Да|||$BE$1📎📎📎Да|||$BQ$1📎📎📎Осн поставщик") -> $BQ$1📎📎📎Да|||$CI$1📎📎📎Осн поставщик|||$CI$1📎📎📎Осн поставщик|||$BE$1📎📎📎Да|||$BE$1📎📎📎Да|||$BQ$1📎📎📎Осн поставщик | IR2: =IFERROR(__xludf.DUMMYFUNCTION(" LAMBDA(cc,тело,комент,комЭкс,BYROW(тело,LAMBDA(r, TEXTJOIN(""|||"",FALSE, ARRAY_CONSTRAIN( Query( TRANSPOSE( { { ARRAYFORMULA( FILTER( ADDRESS(ROW(r), COLUMN(r) ), MOD(COLUMN(r)-cc,3)=0)) }; { ARRAYFORMULA( FILTER( ADDRESS(1, COLUMN(r) ), MOD(COL"&"UMN(r)-cc,3)=0)) }; { ARRAYFORMULA( FILTER( ADDRESS(ROW(r), COLUMN(r) ), MOD(COLUMN(r)-cc,3)=1)) }; { ARRAYFORMULA( FILTER( ADDRESS(ROW(r), COLUMN(r)+1 ), MOD(COLUMN(r)-cc,3)=1)) }; { ARRAYFORMULA( IFERROR(VLOOKUP( FILTER( ADDRESS(1,"&" COLUMN(r) ), MOD(COLUMN(r)-cc,3)=0),комЭкс,2,0 ),"""")) }; { ARRAYFORMULA( IFERROR(VLOOKUP( FILTER( ADDRESS(1, COLUMN(r) ), MOD(COLUMN(r)-cc,3)=0),комЭкс,3,0 ),"""")) }; { ARRAYFORMULA( IFERROR(VLOOKUP( FILTER( ADDRESS(1, COLUMN(r) ), MOD(COLUMN("&"r)-cc,3)=0),комЭкс,4,0 ),"""")) }; { ARRAYFORMULA( IFERROR(VLOOKUP( FILTER( ADDRESS(1, COLUMN(r) ), MOD(COLUMN(r)-cc,3)=0), { TRANSPOSE (FILTER( {SPLIT(INDEX(комент,1,0),""|||"",FALSE,FALSE)}, ARRAYFORMULA( ISODD({SEQUENCE(1, COLUMNS(SPLIT(INDEX(ком"&"ент,1,0),""|||"",FALSE,FALSE) ), 1, 1)})))) , TRANSPOSE (FILTER( {SPLIT(INDEX(комент,1,0),""|||"",FALSE,FALSE)}, ARRAYFORMULA( ISEVEN({SEQUENCE(1, COLUMNS( SPLIT(INDEX(комент,1,0),""|||"",FALSE,FALSE) ), 1, 1)}))))} ,2,0 ),"""")) }; { ARRAYFORMULA( FIL"&"TER( r, MOD(COLUMN(r)-cc,3)=0)) } } ),""Select * Where Col9 is not null Order by Col9"",0),14,8))) )) ( COLUMN('1-1 Сбор КП'!$AA2), '1-1 Сбор КП'!$AA2:$HS2, '1-1 Сбор КП'!$ID2, BYROW( TRANSPOSE(Split('1-1 Сбор КП'!$IQ2,""|||"",FALSE)),LAMBDA(rc,Sp"&"lit(rc,""📎"",FALSE,FALSE))) ) "),"$CI$2|||$CI$1|||$CJ$2|||$CK$2|||||||||Осн поставщик||||||$BQ$2|||$BQ$1|||$BR$2|||$BS$2|||||||||Да||||||$BZ$2|||$BZ$1|||$CA$2|||$CB$2|||||||||||||||$BE$2|||$BE$1|||$BF$2|||$BG$2|||||||||Да||||||$BK$2|||$BK$1|||$BL$2|||$BM$2|||||||||||||||$BH$2|||$BH$1|||$B"&"I$2|||$BJ$2||||||||||||") -> $CI$2|||$CI$1|||$CJ$2|||$CK$2|||||||||Осн поставщик||||||$BQ$2|||$BQ$1|||$BR$2|||$BS$2|||||||||Да||||||$BZ$2|||$BZ$1|||$CA$2|||$CB$2|||||||||||||||$BE$2|||$BE$1|||$BF$2|||$BG$2|||||||||Да||||||$BK$2|||$BK$1|||$BL$2|||$BM$2|||||||||||||||$BH$2|||$BH$1|||$BI$2|||$BJ$2|||||||||||| | IS2: $BQ$1📎📎📎Осн поставщик📎1791373921834|||$BE$1📎📎📎Да📎1791375018979|||$CI$1📎📎📎Осн поставщик📎1791880838684 | IT2: $BQ$1📎📎📎Да📎1791880954777|||$BE$1📎📎📎Да📎1791375018979|||$CI$1📎📎📎Осн поставщик📎1791880838684
A3: Евро | B3: ='4-1 Расчет рентабельности КП'!AJ44 -> #REF! | C3: 2 | D3: Масляный фильтр - Артикул 85062259 | E3: ESG-315 зав.№ 17030008 VS-250; ESM-200 | F3: шт. | G3: 6 | H3: 5 450,00 11 956,00 | I3: 32 700,00 71 736,00 | J3: 7, из них аналог 4 | Q3: =IFERROR(__xludf.DUMMYFUNCTION("""COMPUTED_VALUE"""),7.0) -> 7 | Z3: ID_T002 | BE3: 6900 | BF3: 5 рд | BG3: Масляный фильтр 85062259 [ Аналог SH/O8186 ] | BH3: 17700 | BI3: 18 нед | BJ3: Масляный фильтр - Артикул 85062259 (оригинал) | BK3: 8600 | BL3: нал | BM3: Масляный фильтр - Артикул 85062259 (аналог) | BQ3: 6400 | BR3: 7 рд | BS3: Фильтр масляный 85062259 аналог | BT3: =528.14*1.22*B3 -> #REF! | BU3: нал | BV3: 85062259 Масляный фильтр | BZ3: 11956 | CA3: нал | CB3: Масляный фильтр - Артикул 85062259 | CI3: 5450 | CJ3: 5 рд | CK3: Масляный фильтр 85062259 = SH8186 | HT3: =IFERROR(SMALL($R3:$HS3,VALUE(LEFT(HT$1,1))),"") | HU3: =IFERROR(OFFSET($AA$1,0,MATCH(HT3,$AA3:$HS3,0)),"") | HV3: =IFERROR(SMALL($AA3:$HS3,VALUE(LEFT(HV$1,1))),"") | HW3: =IFERROR(OFFSET($A$1,0,MATCH(HV3,$AA3:$HS3,0)),"") | HX3: =IFERROR(SMALL($AA3:$HS3,VALUE(LEFT(HX$1,1))),"") | HY3: =IFERROR(OFFSET($AA$1,0,MATCH(HX3,$AA3:$HS3,0)),"") | ID3: =IFERROR(__xludf.DUMMYFUNCTION(" IFERROR( TEXTJOIN(""|||"",FALSE , ARRAY_CONSTRAIN( SORT( ARRAYFORMULA(Split(TRANSPOSE (Split(TEXTJOIN(""|||"",TRUE,'1-1 Сбор КП'!$IF3:$IL3),""|||"",FALSE,FALSE) ),""|"",FALSE,FALSE)),3,FALSE ),100,2) ) ,)"),"") | IE3: =IFERROR(__xludf.DUMMYFUNCTION("LAMBDA(cc,тело,комент, комЭкс, порядок,показ, BYROW(тело, LAMBDA(r, TEXTJOIN(""|||"",FALSE,ARRAY_CONSTRAIN( Query( TRANSPOSE( { {ARRAYFORMULA( FILTER( ADDRESS(ROW(r), COLUMN(r) ), MOD(COLUMN(r)-cc,3)=0))}; {ARRAYFORMULA( FILTER( ADDRESS(1, COLUMN(r) ), MO"&"D(COLUMN(r)-cc,3)=0))}; {ARRAYFORMULA( IFERROR(VLOOKUP( FILTER( ADDRESS(1, COLUMN(r) ), MOD(COLUMN(r)-cc,3)=0), { TRANSPOSE (FILTER( {SPLIT(INDEX(комент,1,0),""|||"",FALSE,FALSE)}, ARRAYFORMULA( ISODD({SEQUENCE(1, COLUMNS(SPLIT(INDEX(комент,1,0),""|||"&""",FALSE,FALSE) ), 1, 1)})))) , TRANSPOSE (FILTER( {SPLIT(INDEX(комент,1,0),""|||"",FALSE,FALSE)}, ARRAYFORMULA( ISEVEN({SEQUENCE(1, COLUMNS( SPLIT(INDEX(комент,1,0),""|||"",FALSE,FALSE) ), 1, 1)}))))} ,2,0 ),""""))}; {ARRAYFORMULA( FILTER( ADDRESS(RO"&"W(r), COLUMN(r) ), MOD(COLUMN(r)-cc,3)=1))}; {ARRAYFORMULA( Lambda(f,m,""Подходит: ""& IFERROR( VLOOKUP( f, комЭкс, 4,0 ),""-?"")&"", ""& m&"" ""&IFERROR(VLOOKUP( f, комЭкс, 2,0 ),)&"" ""&IFERROR(VLOOKUP( f, комЭкс, 3,0 ),) ) ( FILTER( ADDRESS(1, COLUM"&"N(r) ), MOD(COLUMN(r)-cc,3)=0), FILTER( r, MOD(COLUMN(r)-cc,3)=2) ) ) }; {ARRAYFORMULA( FILTER( r, MOD(COLUMN(r)-cc,3)=0))}; BYCOL({ARRAYFORMULA( FILTER( ""'1-1 Сбор КП'!""&""R1C""&COLUMN(r) , MOD(COLUMN(r)-cc,3)=0))},LAMBDA(aa, LAMBDA(a,ifs ( IFERR"&"OR(FIND(""(♠)"",a),0)<>0,IFERROR( VLOOKUP(""♠"",порядок,2,FALSE),5), IFERROR(FIND(""(♦️)"",a),0)<>0,IFERROR( VLOOKUP(""♦️"",порядок,2,FALSE),5), IFERROR(FIND(""(♣️)"",a),0)<>0,IFERROR( VLOOKUP(""♣️"",порядок,2,FALSE),5), IFERROR(FIND(""(♥️)"",a),0)<>0,IFE"&"RROR( VLOOKUP(""♥️"",порядок,2,FALSE),5), TRUE,IFERROR( VLOOKUP(""-"",порядок,2,FALSE),5) ))(INDIRECT( aa,FALSE) ) )); BYCOL({ARRAYFORMULA( FILTER( ""'1-1 Сбор КП'!""&""R1C""&COLUMN(r) , MOD(COLUMN(r)-cc,3)=0))},LAMBDA(aa, LAMBDA(a,ifs ( IFERROR(FIND"&"(""(♠)"",a),0)<>0,IFERROR( VLOOKUP(""♠"",показ,2,FALSE),TRUE), IFERROR(FIND(""(♦️)"",a),0)<>0,IFERROR( VLOOKUP(""♦️"",показ,2,FALSE),TRUE), IFERROR(FIND(""(♣️)"",a),0)<>0,IFERROR( VLOOKUP(""♣️"",показ,2,FALSE),TRUE), IFERROR(FIND(""(♥️)"",a),0)<>0,IFERROR"&"( VLOOKUP(""♥️"",показ,2,FALSE),TRUE), TRUE,IFERROR( VLOOKUP(""-"",показ,2,FALSE),TRUE) ))(INDIRECT( aa,FALSE) ) )) }),""Select * Where Col6 is not null and Col8=true Order by Col7, Col6"",0),7,5)) ) ) ) ( COLUMN('1-1 Сбор КП'!$AA3), '1-1 Сбор КП'!$A"&"A3:$HS3, '1-1 Сбор КП'!$ID3, BYROW( TRANSPOSE(Split('1-1 Сбор КП'!$IQ3,""|||"",FALSE)),LAMBDA(rc,Split(rc,""📎"",FALSE,FALSE))), {'3-3 Выбор поставщиков'!$AB$24:$AB$28 , '3-3 Выбор поставщиков'!$AF$24:$AF$28}, {'3-3 Выбор поставщиков'!$AB$24:$AB$28 ,"&" '3-3 Выбор поставщиков'!$AD$24:$AD$28} )"),"$CI$3|||$CI$1||||||$CJ$3|||Подходит: Осн поставщик, Масляный фильтр 85062259 = SH8186 |||$BQ$3|||$BQ$1||||||$BR$3|||Подходит: Да, Фильтр масляный 85062259 аналог |||$BE$3|||$BE$1||||||$BF$3|||Подходит: Да, Масляный фильтр 85062259 [ Аналог SH/O8186 ] "&"|||$BK$3|||$BK$1||||||$BL$3|||Подходит: -?, Масляный фильтр - Артикул 85062259 (аналог) |||$BZ$3|||$BZ$1||||||$CA$3|||Подходит: -?, Масляный фильтр - Артикул 85062259 |||$BH$3|||$BH$1||||||$BI$3|||Подходит: -?, Масляный фильтр - Артикул 85062259 (ориги"&"нал) ") -> $CI$3|||$CI$1||||||$CJ$3|||Подходит: Осн поставщик, Масляный фильтр 85062259 = SH8186 |||$BQ$3|||$BQ$1||||||$BR$3|||Подходит: Да, Фильтр масляный 85062259 аналог |||$BE$3|||$BE$1||||||$BF$3|||Подходит: Да, Масляный фильтр 85062259 [ Аналог SH/O8186 ] |||$BK$3|||$BK$1||||||$BL$3|||Подходит: -?, Масляный фильтр - Артикул 85062259 (аналог) |||$BZ$3|||$BZ$1||||||$CA$3|||Подходит: -?, Масляный фильтр - Артикул 85062259 |||$BH$3|||$BH$1||||||$BI$3|||Подходит: -?, Масляный фильтр - Артикул 85062259 (оригинал) | IQ3: =IFERROR(__xludf.DUMMYFUNCTION(" IFERROR( TEXTJOIN(""|||"",true , BYROW( ARRAY_CONSTRAIN( SORT( ARRAYFORMULA( Split( TRANSPOSE ( Split(TEXTJOIN(""|||"", TRUE, '1-1 Сбор КП'!$IS3:$JF3) ,""|||"",FALSE,FALSE) ),""📎"",FALSE,FALSE"&")),5,FALSE ),100,4) ,LAMBDA(r,TEXTJOIN(""📎"",FALSE ,r)) ) ,))"),"$BQ$1📎📎📎Да|||$CI$1📎📎📎Осн поставщик|||$CI$1📎📎📎Осн поставщик|||$BE$1📎📎📎Да|||$BE$1📎📎📎Да|||$BQ$1📎📎📎Осн поставщик") -> $BQ$1📎📎📎Да|||$CI$1📎📎📎Осн поставщик|||$CI$1📎📎📎Осн поставщик|||$BE$1📎📎📎Да|||$BE$1📎📎📎Да|||$BQ$1📎📎📎Осн поставщик | IR3: =IFERROR(__xludf.DUMMYFUNCTION(" LAMBDA(cc,тело,комент,комЭкс,BYROW(тело,LAMBDA(r, TEXTJOIN(""|||"",FALSE, ARRAY_CONSTRAIN( Query( TRANSPOSE( { { ARRAYFORMULA( FILTER( ADDRESS(ROW(r), COLUMN(r) ), MOD(COLUMN(r)-cc,3)=0)) }; { ARRAYFORMULA( FILTER( ADDRESS(1, COLUMN(r) ), MOD(COL"&"UMN(r)-cc,3)=0)) }; { ARRAYFORMULA( FILTER( ADDRESS(ROW(r), COLUMN(r) ), MOD(COLUMN(r)-cc,3)=1)) }; { ARRAYFORMULA( FILTER( ADDRESS(ROW(r), COLUMN(r)+1 ), MOD(COLUMN(r)-cc,3)=1)) }; { ARRAYFORMULA( IFERROR(VLOOKUP( FILTER( ADDRESS(1,"&" COLUMN(r) ), MOD(COLUMN(r)-cc,3)=0),комЭкс,2,0 ),"""")) }; { ARRAYFORMULA( IFERROR(VLOOKUP( FILTER( ADDRESS(1, COLUMN(r) ), MOD(COLUMN(r)-cc,3)=0),комЭкс,3,0 ),"""")) }; { ARRAYFORMULA( IFERROR(VLOOKUP( FILTER( ADDRESS(1, COLUMN(r) ), MOD(COLUMN("&"r)-cc,3)=0),комЭкс,4,0 ),"""")) }; { ARRAYFORMULA( IFERROR(VLOOKUP( FILTER( ADDRESS(1, COLUMN(r) ), MOD(COLUMN(r)-cc,3)=0), { TRANSPOSE (FILTER( {SPLIT(INDEX(комент,1,0),""|||"",FALSE,FALSE)}, ARRAYFORMULA( ISODD({SEQUENCE(1, COLUMNS(SPLIT(INDEX(ком"&"ент,1,0),""|||"",FALSE,FALSE) ), 1, 1)})))) , TRANSPOSE (FILTER( {SPLIT(INDEX(комент,1,0),""|||"",FALSE,FALSE)}, ARRAYFORMULA( ISEVEN({SEQUENCE(1, COLUMNS( SPLIT(INDEX(комент,1,0),""|||"",FALSE,FALSE) ), 1, 1)}))))} ,2,0 ),"""")) }; { ARRAYFORMULA( FIL"&"TER( r, MOD(COLUMN(r)-cc,3)=0)) } } ),""Select * Where Col9 is not null Order by Col9"",0),14,8))) )) ( COLUMN('1-1 Сбор КП'!$AA3), '1-1 Сбор КП'!$AA3:$HS3, '1-1 Сбор КП'!$ID3, BYROW( TRANSPOSE(Split('1-1 Сбор КП'!$IQ3,""|||"",FALSE)),LAMBDA(rc,Sp"&"lit(rc,""📎"",FALSE,FALSE))) ) "),"$CI$3|||$CI$1|||$CJ$3|||$CK$3|||||||||Осн поставщик||||||$BQ$3|||$BQ$1|||$BR$3|||$BS$3|||||||||Да||||||$BE$3|||$BE$1|||$BF$3|||$BG$3|||||||||Да||||||$BK$3|||$BK$1|||$BL$3|||$BM$3|||||||||||||||$BZ$3|||$BZ$1|||$CA$3|||$CB$3|||||||||||||||$BH$3|||$BH$1|||$B"&"I$3|||$BJ$3||||||||||||") -> $CI$3|||$CI$1|||$CJ$3|||$CK$3|||||||||Осн поставщик||||||$BQ$3|||$BQ$1|||$BR$3|||$BS$3|||||||||Да||||||$BE$3|||$BE$1|||$BF$3|||$BG$3|||||||||Да||||||$BK$3|||$BK$1|||$BL$3|||$BM$3|||||||||||||||$BZ$3|||$BZ$1|||$CA$3|||$CB$3|||||||||||||||$BH$3|||$BH$1|||$BI$3|||$BJ$3|||||||||||| | IS3: $BQ$1📎📎📎Осн поставщик📎1791373995630|||$BE$1📎📎📎Да📎1791375565363|||$CI$1📎📎📎Осн поставщик📎1791880880186 | IT3: $BQ$1📎📎📎Да📎1791880963114|||$BE$1📎📎📎Да📎1791375565363|||$CI$1📎📎📎Осн поставщик📎1791880880186
A4: CNY | B4: ='4-1 Расчет рентабельности КП'!AJ45 -> #REF! | C4: 3 | D4: Воздушный фильтр - Артикул 85067179 | E4: ESG-315 зав.№ F010451; ESG-315 зав.№ 17030008 VS-250; ESM-200; «Gardner Denver» | F4: шт. | G4: 16 | H4: 4 700,00 4 902,00 | I4: 75 200,00 78 432,00 | J4: 8, из них аналог 4 | Q4: =IFERROR(__xludf.DUMMYFUNCTION("""COMPUTED_VALUE"""),8.0) -> 8 | Z4: ID_T003 | BE4: 6400 | BF4: 5 рд | BG4: Воздушный фильтр 85067179 [ Аналог A0584/AG0378 ] | BH4: 19800 | BI4: 18 нед | BJ4: Воздушный фильтр - Артикул 85067179 (оригинал) | BK4: 6500 | BL4: нал | BM4: Воздушный фильтр - Артикул 85067179 (аналог) | BQ4: 4700 | BR4: 7 рд | BS4: Фильтр воздушный 85067179 аналог | BT4: =415.05*1.22*B3 -> #REF! | BU4: нал | BV4: 85067179 Воздушный фильтр | BZ4: 4902 | CA4: нал | CB4: Воздушный фильтр - Артикул 85067179 Аналог | CF4: =639.82*B3 -> #REF! | CG4: 5 д | CH4: Воздушный фильтр (арт. 85067179) | CI4: 5000 | CJ4: 5 рд | CK4: Воздушный фильтр 85067179 = AG0378 | HT4: =IFERROR(SMALL($R4:$HS4,VALUE(LEFT(HT$1,1))),"") | HU4: =IFERROR(OFFSET($AA$1,0,MATCH(HT4,$AA4:$HS4,0)),"") | HV4: =IFERROR(SMALL($AA4:$HS4,VALUE(LEFT(HV$1,1))),"") | HW4: =IFERROR(OFFSET($A$1,0,MATCH(HV4,$AA4:$HS4,0)),"") | HX4: =IFERROR(SMALL($AA4:$HS4,VALUE(LEFT(HX$1,1))),"") | HY4: =IFERROR(OFFSET($AA$1,0,MATCH(HX4,$AA4:$HS4,0)),"") | ID4: =IFERROR(__xludf.DUMMYFUNCTION(" IFERROR( TEXTJOIN(""|||"",FALSE , ARRAY_CONSTRAIN( SORT( ARRAYFORMULA(Split(TRANSPOSE (Split(TEXTJOIN(""|||"",TRUE,'1-1 Сбор КП'!$IF4:$IL4),""|||"",FALSE,FALSE) ),""|"",FALSE,FALSE)),3,FALSE ),100,2) ) ,)"),"") | IE4: =IFERROR(__xludf.DUMMYFUNCTION("LAMBDA(cc,тело,комент, комЭкс, порядок,показ, BYROW(тело, LAMBDA(r, TEXTJOIN(""|||"",FALSE,ARRAY_CONSTRAIN( Query( TRANSPOSE( { {ARRAYFORMULA( FILTER( ADDRESS(ROW(r), COLUMN(r) ), MOD(COLUMN(r)-cc,3)=0))}; {ARRAYFORMULA( FILTER( ADDRESS(1, COLUMN(r) ), MO"&"D(COLUMN(r)-cc,3)=0))}; {ARRAYFORMULA( IFERROR(VLOOKUP( FILTER( ADDRESS(1, COLUMN(r) ), MOD(COLUMN(r)-cc,3)=0), { TRANSPOSE (FILTER( {SPLIT(INDEX(комент,1,0),""|||"",FALSE,FALSE)}, ARRAYFORMULA( ISODD({SEQUENCE(1, COLUMNS(SPLIT(INDEX(комент,1,0),""|||"&""",FALSE,FALSE) ), 1, 1)})))) , TRANSPOSE (FILTER( {SPLIT(INDEX(комент,1,0),""|||"",FALSE,FALSE)}, ARRAYFORMULA( ISEVEN({SEQUENCE(1, COLUMNS( SPLIT(INDEX(комент,1,0),""|||"",FALSE,FALSE) ), 1, 1)}))))} ,2,0 ),""""))}; {ARRAYFORMULA( FILTER( ADDRESS(RO"&"W(r), COLUMN(r) ), MOD(COLUMN(r)-cc,3)=1))}; {ARRAYFORMULA( Lambda(f,m,""Подходит: ""& IFERROR( VLOOKUP( f, комЭкс, 4,0 ),""-?"")&"", ""& m&"" ""&IFERROR(VLOOKUP( f, комЭкс, 2,0 ),)&"" ""&IFERROR(VLOOKUP( f, комЭкс, 3,0 ),) ) ( FILTER( ADDRESS(1, COLUM"&"N(r) ), MOD(COLUMN(r)-cc,3)=0), FILTER( r, MOD(COLUMN(r)-cc,3)=2) ) ) }; {ARRAYFORMULA( FILTER( r, MOD(COLUMN(r)-cc,3)=0))}; BYCOL({ARRAYFORMULA( FILTER( ""'1-1 Сбор КП'!""&""R1C""&COLUMN(r) , MOD(COLUMN(r)-cc,3)=0))},LAMBDA(aa, LAMBDA(a,ifs ( IFERR"&"OR(FIND(""(♠)"",a),0)<>0,IFERROR( VLOOKUP(""♠"",порядок,2,FALSE),5), IFERROR(FIND(""(♦️)"",a),0)<>0,IFERROR( VLOOKUP(""♦️"",порядок,2,FALSE),5), IFERROR(FIND(""(♣️)"",a),0)<>0,IFERROR( VLOOKUP(""♣️"",порядок,2,FALSE),5), IFERROR(FIND(""(♥️)"",a),0)<>0,IFE"&"RROR( VLOOKUP(""♥️"",порядок,2,FALSE),5), TRUE,IFERROR( VLOOKUP(""-"",порядок,2,FALSE),5) ))(INDIRECT( aa,FALSE) ) )); BYCOL({ARRAYFORMULA( FILTER( ""'1-1 Сбор КП'!""&""R1C""&COLUMN(r) , MOD(COLUMN(r)-cc,3)=0))},LAMBDA(aa, LAMBDA(a,ifs ( IFERROR(FIND"&"(""(♠)"",a),0)<>0,IFERROR( VLOOKUP(""♠"",показ,2,FALSE),TRUE), IFERROR(FIND(""(♦️)"",a),0)<>0,IFERROR( VLOOKUP(""♦️"",показ,2,FALSE),TRUE), IFERROR(FIND(""(♣️)"",a),0)<>0,IFERROR( VLOOKUP(""♣️"",показ,2,FALSE),TRUE), IFERROR(FIND(""(♥️)"",a),0)<>0,IFERROR"&"( VLOOKUP(""♥️"",показ,2,FALSE),TRUE), TRUE,IFERROR( VLOOKUP(""-"",показ,2,FALSE),TRUE) ))(INDIRECT( aa,FALSE) ) )) }),""Select * Where Col6 is not null and Col8=true Order by Col7, Col6"",0),7,5)) ) ) ) ( COLUMN('1-1 Сбор КП'!$AA4), '1-1 Сбор КП'!$A"&"A4:$HS4, '1-1 Сбор КП'!$ID4, BYROW( TRANSPOSE(Split('1-1 Сбор КП'!$IQ4,""|||"",FALSE)),LAMBDA(rc,Split(rc,""📎"",FALSE,FALSE))), {'3-3 Выбор поставщиков'!$AB$24:$AB$28 , '3-3 Выбор поставщиков'!$AF$24:$AF$28}, {'3-3 Выбор поставщиков'!$AB$24:$AB$28 ,"&" '3-3 Выбор поставщиков'!$AD$24:$AD$28} )"),"$BQ$4|||$BQ$1||||||$BR$4|||Подходит: Осн поставщик, Фильтр воздушный 85067179 аналог |||$BZ$4|||$BZ$1||||||$CA$4|||Подходит: -?, Воздушный фильтр - Артикул 85067179 Аналог |||$CI$4|||$CI$1||||||$CJ$4|||Подходит: -?, Воздушный фильтр 85067179 = AG0378 "&" |||$BE$4|||$BE$1||||||$BF$4|||Подходит: Да, Воздушный фильтр 85067179 [ Аналог A0584/AG0378 ] |||$BK$4|||$BK$1||||||$BL$4|||Подходит: -?, Воздушный фильтр - Артикул 85067179 (аналог) |||$BH$4|||$BH$1||||||$BI$4|||Подходит: -?, Воздушный фильтр - Артику"&"л 85067179 (оригинал) ") -> $BQ$4|||$BQ$1||||||$BR$4|||Подходит: Осн поставщик, Фильтр воздушный 85067179 аналог |||$BZ$4|||$BZ$1||||||$CA$4|||Подходит: -?, Воздушный фильтр - Артикул 85067179 Аналог |||$CI$4|||$CI$1||||||$CJ$4|||Подходит: -?, Воздушный фильтр 85067179 = AG0378 |||$BE$4|||$BE$1||||||$BF$4|||Подходит: Да, Воздушный фильтр 85067179 [ Аналог A0584/AG0378 ] |||$BK$4|||$BK$1||||||$BL$4|||Подходит: -?, Воздушный фильтр - Артикул 85067179 (аналог) |||$BH$4|||$BH$1||||||$BI$4|||Подходит: -?, Воздушный фильтр - Артикул 85067179 (оригинал) | IQ4: =IFERROR(__xludf.DUMMYFUNCTION(" IFERROR( TEXTJOIN(""|||"",true , BYROW( ARRAY_CONSTRAIN( SORT( ARRAYFORMULA( Split( TRANSPOSE ( Split(TEXTJOIN(""|||"", TRUE, '1-1 Сбор КП'!$IS4:$JF4) ,""|||"",FALSE,FALSE) ),""📎"",FALSE,FALSE"&")),5,FALSE ),100,4) ,LAMBDA(r,TEXTJOIN(""📎"",FALSE ,r)) ) ,))"),"$BE$1📎📎📎Да|||$BQ$1📎📎📎Осн поставщик|||$BQ$1📎📎📎Осн поставщик") -> $BE$1📎📎📎Да|||$BQ$1📎📎📎Осн поставщик|||$BQ$1📎📎📎Осн поставщик | IR4: =IFERROR(__xludf.DUMMYFUNCTION(" LAMBDA(cc,тело,комент,комЭкс,BYROW(тело,LAMBDA(r, TEXTJOIN(""|||"",FALSE, ARRAY_CONSTRAIN( Query( TRANSPOSE( { { ARRAYFORMULA( FILTER( ADDRESS(ROW(r), COLUMN(r) ), MOD(COLUMN(r)-cc,3)=0)) }; { ARRAYFORMULA( FILTER( ADDRESS(1, COLUMN(r) ), MOD(COL"&"UMN(r)-cc,3)=0)) }; { ARRAYFORMULA( FILTER( ADDRESS(ROW(r), COLUMN(r) ), MOD(COLUMN(r)-cc,3)=1)) }; { ARRAYFORMULA( FILTER( ADDRESS(ROW(r), COLUMN(r)+1 ), MOD(COLUMN(r)-cc,3)=1)) }; { ARRAYFORMULA( IFERROR(VLOOKUP( FILTER( ADDRESS(1,"&" COLUMN(r) ), MOD(COLUMN(r)-cc,3)=0),комЭкс,2,0 ),"""")) }; { ARRAYFORMULA( IFERROR(VLOOKUP( FILTER( ADDRESS(1, COLUMN(r) ), MOD(COLUMN(r)-cc,3)=0),комЭкс,3,0 ),"""")) }; { ARRAYFORMULA( IFERROR(VLOOKUP( FILTER( ADDRESS(1, COLUMN(r) ), MOD(COLUMN("&"r)-cc,3)=0),комЭкс,4,0 ),"""")) }; { ARRAYFORMULA( IFERROR(VLOOKUP( FILTER( ADDRESS(1, COLUMN(r) ), MOD(COLUMN(r)-cc,3)=0), { TRANSPOSE (FILTER( {SPLIT(INDEX(комент,1,0),""|||"",FALSE,FALSE)}, ARRAYFORMULA( ISODD({SEQUENCE(1, COLUMNS(SPLIT(INDEX(ком"&"ент,1,0),""|||"",FALSE,FALSE) ), 1, 1)})))) , TRANSPOSE (FILTER( {SPLIT(INDEX(комент,1,0),""|||"",FALSE,FALSE)}, ARRAYFORMULA( ISEVEN({SEQUENCE(1, COLUMNS( SPLIT(INDEX(комент,1,0),""|||"",FALSE,FALSE) ), 1, 1)}))))} ,2,0 ),"""")) }; { ARRAYFORMULA( FIL"&"TER( r, MOD(COLUMN(r)-cc,3)=0)) } } ),""Select * Where Col9 is not null Order by Col9"",0),14,8))) )) ( COLUMN('1-1 Сбор КП'!$AA4), '1-1 Сбор КП'!$AA4:$HS4, '1-1 Сбор КП'!$ID4, BYROW( TRANSPOSE(Split('1-1 Сбор КП'!$IQ4,""|||"",FALSE)),LAMBDA(rc,Sp"&"lit(rc,""📎"",FALSE,FALSE))) ) "),"$BQ$4|||$BQ$1|||$BR$4|||$BS$4|||||||||Осн поставщик||||||$BZ$4|||$BZ$1|||$CA$4|||$CB$4|||||||||||||||$CI$4|||$CI$1|||$CJ$4|||$CK$4|||||||||||||||$BE$4|||$BE$1|||$BF$4|||$BG$4|||||||||Да||||||$BK$4|||$BK$1|||$BL$4|||$BM$4|||||||||||||||$BH$4|||$BH$1|||$BI$"&"4|||$BJ$4||||||||||||") -> $BQ$4|||$BQ$1|||$BR$4|||$BS$4|||||||||Осн поставщик||||||$BZ$4|||$BZ$1|||$CA$4|||$CB$4|||||||||||||||$CI$4|||$CI$1|||$CJ$4|||$CK$4|||||||||||||||$BE$4|||$BE$1|||$BF$4|||$BG$4|||||||||Да||||||$BK$4|||$BK$1|||$BL$4|||$BM$4|||||||||||||||$BH$4|||$BH$1|||$BI$4|||$BJ$4|||||||||||| | IS4: $BQ$1📎📎📎Осн поставщик📎1791374014362 | IT4: $BQ$1📎📎📎Осн поставщик📎1791374014362|||$BE$1📎📎📎Да📎1791375584506
C5: 4 | D5: Термостат в сборе ESM-200; «Gardner Denver» | E5: ESM-200; «Gardner Denver» | F5: шт. | G5: 2 | H5: 0,00 0,00 | I5: 0,00 0,00 | J5: Мало, всего 0 | Q5: =IFERROR(__xludf.DUMMYFUNCTION("""COMPUTED_VALUE"""),0.0) -> 0 | Z5: ID_T004 | HT5: =IFERROR(SMALL($R5:$HS5,VALUE(LEFT(HT$1,1))),"") | HU5: =IFERROR(OFFSET($AA$1,0,MATCH(HT5,$AA5:$HS5,0)),"") | HV5: =IFERROR(SMALL($AA5:$HS5,VALUE(LEFT(HV$1,1))),"") | HW5: =IFERROR(OFFSET($A$1,0,MATCH(HV5,$AA5:$HS5,0)),"") | HX5: =IFERROR(SMALL($AA5:$HS5,VALUE(LEFT(HX$1,1))),"") | HY5: =IFERROR(OFFSET($AA$1,0,MATCH(HX5,$AA5:$HS5,0)),"") | ID5: =IFERROR(__xludf.DUMMYFUNCTION(" IFERROR( TEXTJOIN(""|||"",FALSE , ARRAY_CONSTRAIN( SORT( ARRAYFORMULA(Split(TRANSPOSE (Split(TEXTJOIN(""|||"",TRUE,'1-1 Сбор КП'!$IF5:$IL5),""|||"",FALSE,FALSE) ),""|"",FALSE,FALSE)),3,FALSE ),100,2) ) ,)"),"") | IE5: =IFERROR(__xludf.DUMMYFUNCTION("LAMBDA(cc,тело,комент, комЭкс, порядок,показ, BYROW(тело, LAMBDA(r, TEXTJOIN(""|||"",FALSE,ARRAY_CONSTRAIN( Query( TRANSPOSE( { {ARRAYFORMULA( FILTER( ADDRESS(ROW(r), COLUMN(r) ), MOD(COLUMN(r)-cc,3)=0))}; {ARRAYFORMULA( FILTER( ADDRESS(1, COLUMN(r) ), MO"&"D(COLUMN(r)-cc,3)=0))}; {ARRAYFORMULA( IFERROR(VLOOKUP( FILTER( ADDRESS(1, COLUMN(r) ), MOD(COLUMN(r)-cc,3)=0), { TRANSPOSE (FILTER( {SPLIT(INDEX(комент,1,0),""|||"",FALSE,FALSE)}, ARRAYFORMULA( ISODD({SEQUENCE(1, COLUMNS(SPLIT(INDEX(комент,1,0),""|||"&""",FALSE,FALSE) ), 1, 1)})))) , TRANSPOSE (FILTER( {SPLIT(INDEX(комент,1,0),""|||"",FALSE,FALSE)}, ARRAYFORMULA( ISEVEN({SEQUENCE(1, COLUMNS( SPLIT(INDEX(комент,1,0),""|||"",FALSE,FALSE) ), 1, 1)}))))} ,2,0 ),""""))}; {ARRAYFORMULA( FILTER( ADDRESS(RO"&"W(r), COLUMN(r) ), MOD(COLUMN(r)-cc,3)=1))}; {ARRAYFORMULA( Lambda(f,m,""Подходит: ""& IFERROR( VLOOKUP( f, комЭкс, 4,0 ),""-?"")&"", ""& m&"" ""&IFERROR(VLOOKUP( f, комЭкс, 2,0 ),)&"" ""&IFERROR(VLOOKUP( f, комЭкс, 3,0 ),) ) ( FILTER( ADDRESS(1, COLUM"&"N(r) ), MOD(COLUMN(r)-cc,3)=0), FILTER( r, MOD(COLUMN(r)-cc,3)=2) ) ) }; {ARRAYFORMULA( FILTER( r, MOD(COLUMN(r)-cc,3)=0))}; BYCOL({ARRAYFORMULA( FILTER( ""'1-1 Сбор КП'!""&""R1C""&COLUMN(r) , MOD(COLUMN(r)-cc,3)=0))},LAMBDA(aa, LAMBDA(a,ifs ( IFERR"&"OR(FIND(""(♠)"",a),0)<>0,IFERROR( VLOOKUP(""♠"",порядок,2,FALSE),5), IFERROR(FIND(""(♦️)"",a),0)<>0,IFERROR( VLOOKUP(""♦️"",порядок,2,FALSE),5), IFERROR(FIND(""(♣️)"",a),0)<>0,IFERROR( VLOOKUP(""♣️"",порядок,2,FALSE),5), IFERROR(FIND(""(♥️)"",a),0)<>0,IFE"&"RROR( VLOOKUP(""♥️"",порядок,2,FALSE),5), TRUE,IFERROR( VLOOKUP(""-"",порядок,2,FALSE),5) ))(INDIRECT( aa,FALSE) ) )); BYCOL({ARRAYFORMULA( FILTER( ""'1-1 Сбор КП'!""&""R1C""&COLUMN(r) , MOD(COLUMN(r)-cc,3)=0))},LAMBDA(aa, LAMBDA(a,ifs ( IFERROR(FIND"&"(""(♠)"",a),0)<>0,IFERROR( VLOOKUP(""♠"",показ,2,FALSE),TRUE), IFERROR(FIND(""(♦️)"",a),0)<>0,IFERROR( VLOOKUP(""♦️"",показ,2,FALSE),TRUE), IFERROR(FIND(""(♣️)"",a),0)<>0,IFERROR( VLOOKUP(""♣️"",показ,2,FALSE),TRUE), IFERROR(FIND(""(♥️)"",a),0)<>0,IFERROR"&"( VLOOKUP(""♥️"",показ,2,FALSE),TRUE), TRUE,IFERROR( VLOOKUP(""-"",показ,2,FALSE),TRUE) ))(INDIRECT( aa,FALSE) ) )) }),""Select * Where Col6 is not null and Col8=true Order by Col7, Col6"",0),7,5)) ) ) ) ( COLUMN('1-1 Сбор КП'!$AA5), '1-1 Сбор КП'!$A"&"A5:$HS5, '1-1 Сбор КП'!$ID5, BYROW( TRANSPOSE(Split('1-1 Сбор КП'!$IQ5,""|||"",FALSE)),LAMBDA(rc,Split(rc,""📎"",FALSE,FALSE))), {'3-3 Выбор поставщиков'!$AB$24:$AB$28 , '3-3 Выбор поставщиков'!$AF$24:$AF$28}, {'3-3 Выбор поставщиков'!$AB$24:$AB$28 ,"&" '3-3 Выбор поставщиков'!$AD$24:$AD$28} )"),"#N/A") -> #N/A | IQ5: =IFERROR(__xludf.DUMMYFUNCTION(" IFERROR( TEXTJOIN(""|||"",true , BYROW( ARRAY_CONSTRAIN( SORT( ARRAYFORMULA( Split( TRANSPOSE ( Split(TEXTJOIN(""|||"", TRUE, '1-1 Сбор КП'!$IS5:$JF5) ,""|||"",FALSE,FALSE) ),""📎"",FALSE,FALSE"&")),5,FALSE ),100,4) ,LAMBDA(r,TEXTJOIN(""📎"",FALSE ,r)) ) ,))"),"") | IR5: =IFERROR(__xludf.DUMMYFUNCTION(" LAMBDA(cc,тело,комент,комЭкс,BYROW(тело,LAMBDA(r, TEXTJOIN(""|||"",FALSE, ARRAY_CONSTRAIN( Query( TRANSPOSE( { { ARRAYFORMULA( FILTER( ADDRESS(ROW(r), COLUMN(r) ), MOD(COLUMN(r)-cc,3)=0)) }; { ARRAYFORMULA( FILTER( ADDRESS(1, COLUMN(r) ), MOD(COL"&"UMN(r)-cc,3)=0)) }; { ARRAYFORMULA( FILTER( ADDRESS(ROW(r), COLUMN(r) ), MOD(COLUMN(r)-cc,3)=1)) }; { ARRAYFORMULA( FILTER( ADDRESS(ROW(r), COLUMN(r)+1 ), MOD(COLUMN(r)-cc,3)=1)) }; { ARRAYFORMULA( IFERROR(VLOOKUP( FILTER( ADDRESS(1,"&" COLUMN(r) ), MOD(COLUMN(r)-cc,3)=0),комЭкс,2,0 ),"""")) }; { ARRAYFORMULA( IFERROR(VLOOKUP( FILTER( ADDRESS(1, COLUMN(r) ), MOD(COLUMN(r)-cc,3)=0),комЭкс,3,0 ),"""")) }; { ARRAYFORMULA( IFERROR(VLOOKUP( FILTER( ADDRESS(1, COLUMN(r) ), MOD(COLUMN("&"r)-cc,3)=0),комЭкс,4,0 ),"""")) }; { ARRAYFORMULA( IFERROR(VLOOKUP( FILTER( ADDRESS(1, COLUMN(r) ), MOD(COLUMN(r)-cc,3)=0), { TRANSPOSE (FILTER( {SPLIT(INDEX(комент,1,0),""|||"",FALSE,FALSE)}, ARRAYFORMULA( ISODD({SEQUENCE(1, COLUMNS(SPLIT(INDEX(ком"&"ент,1,0),""|||"",FALSE,FALSE) ), 1, 1)})))) , TRANSPOSE (FILTER( {SPLIT(INDEX(комент,1,0),""|||"",FALSE,FALSE)}, ARRAYFORMULA( ISEVEN({SEQUENCE(1, COLUMNS( SPLIT(INDEX(комент,1,0),""|||"",FALSE,FALSE) ), 1, 1)}))))} ,2,0 ),"""")) }; { ARRAYFORMULA( FIL"&"TER( r, MOD(COLUMN(r)-cc,3)=0)) } } ),""Select * Where Col9 is not null Order by Col9"",0),14,8))) )) ( COLUMN('1-1 Сбор КП'!$AA5), '1-1 Сбор КП'!$AA5:$HS5, '1-1 Сбор КП'!$ID5, BYROW( TRANSPOSE(Split('1-1 Сбор КП'!$IQ5,""|||"",FALSE)),LAMBDA(rc,Sp"&"lit(rc,""📎"",FALSE,FALSE))) ) "),"#N/A") -> #N/A
